Workbook
Name CDIDs_x: #REF!
Name conf_status_code: #REF!
Name conf_status_code: #REF!
Name CSDB_data: #REF!
Name CSDB_download: '[1]download cpsa'!$A$4:$GX$1205
Name CSDB_download_x: '[1]download cpsa'!$A$4:$GX$4
Name CSDB_download_y: '[1]download cpsa'!$A$4:$A$1205
Name Date_y: #REF!
Name Obs_conf_code: [2]table_id!$II$2:$II$6
Name organisation_code: #REF!
Name organisation_code: #REF!
Name Price_Code: #REF!
Name Price_Code: #REF!
Name Price_Codes: #REF!
Name Price_Codes: #REF!
Name Prices_codes: [2]table_id!$IO$2:$IO$4

Sheet CPA_COICOP_map
A1: COICOP | B1: CPA | C1: CPA Weight in COICOP | D1: Proportion of CPA in each COICOP | E1: CPA (long) | F1: CPA label | G1: Effect (CPA) | H1: Total domestic use (CPA) | I1: my_coicop
A2: 01.1.1 | B2: 10.6 | C2: 0.229 | D2: 1 | E2: CPA_C106 | F2: Grain mill products, starches and starch products | G2: =VLOOKUP(E2,Effects!A:J,10,FALSE) -> 0.68377747 | H2: =VLOOKUP(E2,IOT!$A$6:$DO$115, 119, FALSE) -> 5525 | I2: 1
A3: 01.1.1 | B3: 10.7 | C3: 0.586 | D3: 1 | E3: CPA_C107 | F3: Bakery and farinaceous products | G3: =VLOOKUP(E3,Effects!A:J,10,FALSE) -> 0.83732069 | H3: =VLOOKUP(E3,IOT!$A$6:$DO$115, 119, FALSE) -> 10442 | I3: 1
A4: 01.1.1 | B4: 10.8 | C4: 0.186 | D4: 0.1671636 | E4: CPA_C108 | F4: Other food products | G4: =VLOOKUP(E4,Effects!A:J,10,FALSE) -> 0.80208712 | H4: =VLOOKUP(E4,IOT!$A$6:$DO$115, 119, FALSE) -> 15111 | I4: 1
A5: 01.1.2 | B5: 10.1 | C5: 1 | D5: 1 | E5: CPA_C101 | F5: Preserved meat and meat products | G5: =VLOOKUP(E5,Effects!A:J,10,FALSE) -> 0.8207624 | H5: =VLOOKUP(E5,IOT!$A$6:$DO$115, 119, FALSE) -> 20383 | I5: 1
A6: 01.1.3 | B6: 3 | C6: 0.14 | D6: 1 | E6: CPA_A03 | F6: Fish and other fishing products; aquaculture products; support services to fishing | G6: =VLOOKUP(E6,Effects!A:J,10,FALSE) -> 0.72841082 | H6: =VLOOKUP(E6,IOT!$A$6:$DO$115, 119, FALSE) -> 2084 | I6: 1
A7: 01.1.3 | B7: 10.2-3 | C7: 0.86 | D7: 0.23261355 | E7: CPA_C102_3 | F7: Processed and preserved fish, crustaceans, molluscs, fruit and vegetables | G7: =VLOOKUP(E7,Effects!A:J,10,FALSE) -> 0.80865224 | H7: =VLOOKUP(E7,IOT!$A$6:$DO$115, 119, FALSE) -> 9416 | I7: 1
A8: 01.1.4 | B8: 1 | C8: 0.103 | D8: 0.067762416 | E8: CPA_A01 | F8: Products of agriculture, hunting and related services | G8: =VLOOKUP(E8,Effects!A:J,10,FALSE) -> 0.82751497 | H8: =VLOOKUP(E8,IOT!$A$6:$DO$115, 119, FALSE) -> 28145 | I8: 1
A9: 01.1.4 | B9: 10.5 | C9: 0.897 | D9: 0.84610129 | E9: CPA_C105 | F9: Dairy products | G9: =VLOOKUP(E9,Effects!A:J,10,FALSE) -> 0.83098006 | H9: =VLOOKUP(E9,IOT!$A$6:$DO$115, 119, FALSE) -> 9693 | I9: 1
A10: 01.1.5 | B10: 10.4 | C10: 0.614 | D10: 1 | E10: CPA_C104 | F10: Vegetable and animal oils and fats | G10: =VLOOKUP(E10,Effects!A:J,10,FALSE) -> 0.60233539 | H10: =VLOOKUP(E10,IOT!$A$6:$DO$115, 119, FALSE) -> 1717 | I10: 1
A11: 01.1.5 | B11: 10.5 | C11: 0.386 | D11: 0.063540866 | E11: CPA_C105 | F11: Dairy products | G11: =VLOOKUP(E11,Effects!A:J,10,FALSE) -> 0.83098006 | H11: =VLOOKUP(E11,IOT!$A$6:$DO$115, 119, FALSE) -> 9693 | I11: 1
A12: 01.1.6 | B12: 1 | C12: 0.93 | D12: 0.40853261 | E12: CPA_A01 | F12: Products of agriculture, hunting and related services | G12: =VLOOKUP(E12,Effects!A:J,10,FALSE) -> 0.82751497 | H12: =VLOOKUP(E12,IOT!$A$6:$DO$115, 119, FALSE) -> 28145 | I12: 1
A13: 01.1.6 | B13: 10.2-3 | C13: 0.069 | D13: 0.037974684 | E13: CPA_C102_3 | F13: Processed and preserved fish, crustaceans, molluscs, fruit and vegetables | G13: =VLOOKUP(E13,Effects!A:J,10,FALSE) -> 0.80865224 | H13: =VLOOKUP(E13,IOT!$A$6:$DO$115, 119, FALSE) -> 9416 | I13: 1
A14: 01.1.6 | B14: 10.8 | C14: 0.001 | D14: 0.00064817215 | E14: CPA_C108 | F14: Other food products | G14: =VLOOKUP(E14,Effects!A:J,10,FALSE) -> 0.80208712 | H14: =VLOOKUP(E14,IOT!$A$6:$DO$115, 119, FALSE) -> 15111 | I14: 1
A15: 01.1.7 | B15: 1 | C15: 0.443 | D15: 0.33999881 | E15: CPA_A01 | F15: Products of agriculture, hunting and related services | G15: =VLOOKUP(E15,Effects!A:J,10,FALSE) -> 0.82751497 | H15: =VLOOKUP(E15,IOT!$A$6:$DO$115, 119, FALSE) -> 28145 | I15: 1
A16: 01.1.7 | B16: 10.2-3 | C16: 0.557 | D16: 0.53670886 | E16: CPA_C102_3 | F16: Processed and preserved fish, crustaceans, molluscs, fruit and vegetables | G16: =VLOOKUP(E16,Effects!A:J,10,FALSE) -> 0.80865224 | H16: =VLOOKUP(E16,IOT!$A$6:$DO$115, 119, FALSE) -> 9416 | I16: 1
A17: 01.1.8 | B17: 10.2-3 | C17: 0.041 | D17: 0.030379747 | E17: CPA_C102_3 | F17: Processed and preserved fish, crustaceans, molluscs, fruit and vegetables | G17: =VLOOKUP(E17,Effects!A:J,10,FALSE) -> 0.80865224 | H17: =VLOOKUP(E17,IOT!$A$6:$DO$115, 119, FALSE) -> 9416 | I17: 1
A18: 01.1.8 | B18: 10.5 | C18: 0.107 | D18: 0.090357844 | E18: CPA_C105 | F18: Dairy products | G18: =VLOOKUP(E18,Effects!A:J,10,FALSE) -> 0.83098006 | H18: =VLOOKUP(E18,IOT!$A$6:$DO$115, 119, FALSE) -> 9693 | I18: 1
A19: 01.1.8 | B19: 10.8 | C19: 0.851 | D19: 0.5447887 | E19: CPA_C108 | F19: Other food products | G19: =VLOOKUP(E19,Effects!A:J,10,FALSE) -> 0.80208712 | H19: =VLOOKUP(E19,IOT!$A$6:$DO$115, 119, FALSE) -> 15111 | I19: 1
A20: 01.1.9 | B20: 1 | C20: 0.25 | D20: 0.03595799 | E20: CPA_A01 | F20: Products of agriculture, hunting and related services | G20: =VLOOKUP(E20,Effects!A:J,10,FALSE) -> 0.82751497 | H20: =VLOOKUP(E20,IOT!$A$6:$DO$115, 119, FALSE) -> 28145 | I20: 1
A21: 01.1.9 | B21: 10.8 | C21: 0.75 | D21: 0.11790251 | E21: CPA_C108 | F21: Other food products | G21: =VLOOKUP(E21,Effects!A:J,10,FALSE) -> 0.80208712 | H21: =VLOOKUP(E21,IOT!$A$6:$DO$115, 119, FALSE) -> 15111 | I21: 1
A22: 01.2.1 | B22: 10.8 | C22: 1 | D22: 0.16949702 | E22: CPA_C108 | F22: Other food products | G22: =VLOOKUP(E22,Effects!A:J,10,FALSE) -> 0.80208712 | H22: =VLOOKUP(E22,IOT!$A$6:$DO$115, 119, FALSE) -> 15111 | I22: 1
A23: 01.2.2 | B23: 10.2-3 | C23: 0.261 | D23: 0.16232316 | E23: CPA_C102_3 | F23: Processed and preserved fish, crustaceans, molluscs, fruit and vegetables | G23: =VLOOKUP(E23,Effects!A:J,10,FALSE) -> 0.80865224 | H23: =VLOOKUP(E23,IOT!$A$6:$DO$115, 119, FALSE) -> 9416 | I23: 1
A24: 01.2.2 | B24: 11.07 | C24: 0.739 | D24: 1 | E24: CPA_C1107 | F24: Soft drinks | G24: =VLOOKUP(E24,Effects!A:J,10,FALSE) -> 0.79066311 | H24: =VLOOKUP(E24,IOT!$A$6:$DO$115, 119, FALSE) -> 4930 | I24: 1
A25: 02.1.1 | B25: 11.01-6 | C25: 1 | D25: 0.28198341 | E25: CPA_C11.01-6 & C12 | F25: Alcoholic beverages & Tobacco products | G25: =VLOOKUP(E25,Effects!A:J,10,FALSE) -> 0.79321116 | H25: =VLOOKUP(E25,IOT!$A$6:$DO$115, 119, FALSE) -> 9572 | I25: 2
A26: 02.1.2 | B26: 11.01-6 | C26: 1 | D26: 0.46891359 | E26: CPA_C11.01-6 & C12 | F26: Alcoholic beverages & Tobacco products | G26: =VLOOKUP(E26,Effects!A:J,10,FALSE) -> 0.79321116 | H26: =VLOOKUP(E26,IOT!$A$6:$DO$115, 119, FALSE) -> 9572 | I26: 2
A27: 02.1.3 | B27: 11.01-6 | C27: 1 | D27: 0.24910299 | E27: CPA_C11.01-6 & C12 | F27: Alcoholic beverages & Tobacco products | G27: =VLOOKUP(E27,Effects!A:J,10,FALSE) -> 0.79321116 | H27: =VLOOKUP(E27,IOT!$A$6:$DO$115, 119, FALSE) -> 9572 | I27: 2
A28: 2.2 | B28: 12 | C28: 1 | D28: 1 | E28: CPA_C11.01-6 & C12 | F28: Alcoholic beverages & Tobacco products | G28: =VLOOKUP(E28,Effects!A:J,10,FALSE) -> 0.79321116 | H28: =VLOOKUP(E28,IOT!$A$6:$DO$115, 119, FALSE) -> 9572 | I28: 2
A29: 2.3 | B29: 21 | C29: 1 | D29: 0.56619385 | E29: CPA_C21 | F29: Basic pharmaceutical products and pharmaceutical preparations | G29: =VLOOKUP(E29,Effects!A:J,10,FALSE) -> 0.75185057 | H29: =VLOOKUP(E29,IOT!$A$6:$DO$115, 119, FALSE) -> 25174 | I29: 2
A30: 03.1.1 | B30: 13 | C30: 1 | D30: 0.053561491 | E30: CPA_C13 | F30: Textiles | G30: =VLOOKUP(E30,Effects!A:J,10,FALSE) -> 0.79013404 | H30: =VLOOKUP(E30,IOT!$A$6:$DO$115, 119, FALSE) -> 6589 | I30: 3
A31: 03.1.2 | B31: 13 | C31: 0.02 | D31: 0.061421814 | E31: CPA_C13 | F31: Textiles | G31: =VLOOKUP(E31,Effects!A:J,10,FALSE) -> 0.79013404 | H31: =VLOOKUP(E31,IOT!$A$6:$DO$115, 119, FALSE) -> 6589 | I31: 3
A32: 03.1.2 | B32: 14 | C32: 0.98 | D32: 0.96860405 | E32: CPA_C14 | F32: Wearing apparel | G32: =VLOOKUP(E32,Effects!A:J,10,FALSE) -> 0.88290355 | H32: =VLOOKUP(E32,IOT!$A$6:$DO$115, 119, FALSE) -> 4007 | I32: 3
A33: 03.1.3 | B33: 13 | C33: 0.4 | D33: 0.097662771 | E33: CPA_C13 | F33: Textiles | G33: =VLOOKUP(E33,Effects!A:J,10,FALSE) -> 0.79013404 | H33: =VLOOKUP(E33,IOT!$A$6:$DO$115, 119, FALSE) -> 6589 | I33: 3
A34: 03.1.3 | B34: 14 | C34: 0.4 | D34: 0.031395946 | E34: CPA_C14 | F34: Wearing apparel | G34: =VLOOKUP(E34,Effects!A:J,10,FALSE) -> 0.88290355 | H34: =VLOOKUP(E34,IOT!$A$6:$DO$115, 119, FALSE) -> 4007 | I34: 3
A35: 03.1.3 | B35: 32 | C35: 0.2 | D35: 0.027129386 | E35: CPA_C32 | F35: Other manufactured goods | G35: =VLOOKUP(E35,Effects!A:J,10,FALSE) -> 0.74699996 | H35: =VLOOKUP(E35,IOT!$A$6:$DO$115, 119, FALSE) -> 9742 | I35: 3
A36: 03.1.4 | B36: 77 | C36: 0.1 | D36: 0.010616008 | E36: CPA_N77 | F36: Rental and leasing services | G36: =VLOOKUP(E36,Effects!A:J,10,FALSE) -> 0.89792723 | H36: =VLOOKUP(E36,IOT!$A$6:$DO$115, 119, FALSE) -> 43159 | I36: 3
A37: 03.1.4 | B37: 95 | C37: 0.102 | D37: 0.070902394 | E37: CPA_S95 | F37: Repair services of computers and personal and household goods | G37: =VLOOKUP(E37,Effects!A:J,10,FALSE) -> 0.87457352 | H37: =VLOOKUP(E37,IOT!$A$6:$DO$115, 119, FALSE) -> 3698 | I37: 3
A38: 03.1.4 | B38: 96 | C38: 0.798 | D38: 0.034591195 | E38: CPA_S96 | F38: Other personal services | G38: =VLOOKUP(E38,Effects!A:J,10,FALSE) -> 0.92859795 | H38: =VLOOKUP(E38,IOT!$A$6:$DO$115, 119, FALSE) -> 28154 | I38: 3
A39: 03.2.1 | B39: 15 | C39: 1 | D39: 0.81317422 | E39: CPA_C15 | F39: Leather and related products | G39: =VLOOKUP(E39,Effects!A:J,10,FALSE) -> 0.78616306 | H39: =VLOOKUP(E39,IOT!$A$6:$DO$115, 119, FALSE) -> 985 | I39: 3
A40: 03.2.2 | B40: 95 | C40: 1 | D40: 0.046040516 | E40: CPA_S95 | F40: Repair services of computers and personal and household goods | G40: =VLOOKUP(E40,Effects!A:J,10,FALSE) -> 0.87457352 | H40: =VLOOKUP(E40,IOT!$A$6:$DO$115, 119, FALSE) -> 3698 | I40: 3
...

Sheet Effects
A1: CPA | B1: Product | C1: Intermediate consumption at basic prices | D1: Use of imported products, cif | E1: Taxes less subsidies on products | F1: Intermediate consumption at purchaser's prices | G1: Compensation of employees | H1: Gross operating surplus and mixed income | I1: Taxes less subsidies on production | J1: Gross value added | K1: Output
A2: CPA_T97 | B2: Services of households as employers of domestic personnel | C2: 0 | D2: 0 | E2: 0 | F2: 0 | G2: 1 | H2: 0 | I2: 0 | J2: 1 | K2: 1
A3: CPA_L68A | B3: Owner-Occupiers' Housing Services | C3: 0.25538492 | D3: 0.017625998 | E3: 0.0070672235 | F3: 0.28007814 | G3: 0.062559812 | H3: 0.91029111 | I3: 0.0024558571 | J3: 0.97530678 | K3: 1.2553849
A4: CPA_E37 | B4: Sewerage services; sewage sludge | C4: 0.2851117 | D4: 0.020576463 | E4: 0.017572994 | F4: 0.32326116 | G4: 0.21433895 | H4: 0.72997157 | I4: 0.017540027 | J4: 0.96185054 | K4: 1.2851117
A5: CPA_M691 | B5: Legal services | C5: 0.32448298 | D5: 0.055880566 | E5: 0.0048470426 | F5: 0.38521059 | G5: 0.4406494 | H5: 0.486921 | I5: 0.01170199 | J5: 0.93927239 | K5: 1.324483
A6: CPA_E36 | B6: Natural water; water treatment and supply services | C6: 0.50482428 | D6: 0.055940858 | E6: 0.0090839616 | F6: 0.56984909 | G6: 0.29597989 | H6: 0.58259619 | I6: 0.056399095 | J6: 0.93497518 | K6: 1.5048243
A7: CPA_P85 | B7: Education services | C7: 0.39113688 | D7: 0.044077898 | E7: 0.025707028 | F7: 0.4609218 | G7: 0.68582909 | H7: 0.23800488 | I7: 0.006381111 | J7: 0.93021507 | K7: 1.3911369
A8: CPA_S96 | B8: Other personal services | C8: 0.29134672 | D8: 0.045913569 | E8: 0.025488486 | F8: 0.36274878 | G8: 0.31214023 | H8: 0.60517805 | I8: 0.011279668 | J8: 0.92859795 | K8: 1.2913467
A9: CPA_M75 | B9: Veterinary services | C9: 0.3402635 | D9: 0.067818812 | E9: 0.005963092 | F9: 0.41404541 | G9: 0.585303 | H9: 0.36240078 | I9: -0.021485679 | J9: 0.9262181 | K9: 1.3402635
A10: CPA_N80 | B10: Security and investigation services | C10: 0.6749701 | D10: 0.06818796 | E10: 0.0094862973 | F10: 0.75264435 | G10: 0.54226277 | H10: 0.37288421 | I10: 0.0071787614 | J10: 0.92232574 | K10: 1.6749701
A11: CPA_L683 | B11: Real estate services on a fee or contract basis | C11: 0.62180659 | D11: 0.06298211 | E11: 0.015267659 | F11: 0.70005636 | G11: 0.5895574 | H11: 0.29868469 | I11: 0.033508137 | J11: 0.92175023 | K11: 1.6218066
A12: CPA_E39 | B12: Remediation services and other waste management services | C12: 0.66213528 | D12: 0.065925981 | E12: 0.015681675 | F12: 0.74374293 | G12: 0.44130419 | H12: 0.46957361 | I12: 0.0075145441 | J12: 0.91839234 | K12: 1.6621353
A13: CPA_M692 | B13: Accounting, bookkeeping and auditing services; tax consulting services | C13: 0.25856588 | D13: 0.076781635 | E13: 0.0061140856 | F13: 0.3414616 | G13: 0.56523812 | H13: 0.34514997 | I13: 0.006716191 | J13: 0.91710428 | K13: 1.2585659
... A106: CPA_C19 | B106: Coke and refined petroleum products | C106: 0.19405226 | D106: 0.77281371 | E106: 0.030916971 | F106: 0.99778294 | G106: 0.06654902 | H106: 0.12419413 | I106: 0.0055261628 | J106: 0.19626932 | K106: 1.1940523

Sheet IOT
A1: 2019 Input-Output Analytical Tables
A2: Input-Output table (domestic use, basic prices, product by product), £ million
A3: MENU | DO3: =COLUMN() -> 119
B4: CPA | C4: CPA_A01 | D4: CPA_A02 | E4: CPA_A03 | F4: CPA_B05 | G4: CPA_B06 & B07 | H4: CPA_B08 | I4: CPA_B09 | J4: CPA_C101 | K4: CPA_C102_3 | L4: CPA_C104 | M4: CPA_C105 | N4: CPA_C106 | O4: CPA_C107 | P4: CPA_C108 | Q4: CPA_C109 | R4: CPA_C11.01-6 & C12 | S4: CPA_C1107 | T4: CPA_C13 | U4: CPA_C14 | V4: CPA_C15 | W4: CPA_C16 | X4: CPA_C17 | Y4: CPA_C18 | Z4: CPA_C19 | AA4: CPA_C203 | AB4: CPA_C204 | AC4: CPA_C205 | AD4: CPA_C20A | AE4: CPA_C20B | AF4: CPA_C20C | AG4: CPA_C21 | AH4: CPA_C22 | AI4: CPA_C235_6 | AJ4: CPA_C23OTHER | AK4: CPA_C241_3 | AL4: CPA_C244_5 | AM4: CPA_C254 | AN4: CPA_C25OTHER | AO4: CPA_C26 | AP4: CPA_C27 | AQ4: CPA_C28 | AR4: CPA_C29 | AS4: CPA_C301 | AT4: CPA_C303 | AU4: CPA_C30OTHER | AV4: CPA_C31 | AW4: CPA_C32 | AX4: CPA_C3315 | AY4: CPA_C3316 | AZ4: CPA_C33OTHER | BA4: CPA_D351 | BB4: CPA_D352_3 | BC4: CPA_E36 | BD4: CPA_E37 | BE4: CPA_E38 | BF4: CPA_E39 | BG4: CPA_F41, F42 & F43 | BH4: CPA_G45 | BI4: CPA_G46 | BJ4: CPA_G47 | BK4: CPA_H491_2 | BL4: CPA_H493_5 | BM4: CPA_H50 | BN4: CPA_H51 | BO4: CPA_H52 | BP4: CPA_H53 | BQ4: CPA_I55 | BR4: CPA_I56 | BS4: CPA_J58 | BT4: CPA_J59 & J60 | BU4: CPA_J61 | BV4: CPA_J62 | BW4: CPA_J63 | BX4: CPA_K64 | BY4: CPA_K65.1-2 & K65.3 | BZ4: CPA_K66 | CA4: CPA_L683 | CB4: CPA_L68A | CC4: CPA_L68BXL683 | CD4: CPA_M691 | CE4: CPA_M692 | CF4: CPA_M70 | CG4: CPA_M71 | CH4: CPA_M72 | CI4: CPA_M73 | CJ4: CPA_M74 | CK4: CPA_M75 | CL4: CPA_N77 | CM4: CPA_N78 | CN4: CPA_N79 | CO4: CPA_N80 | CP4: CPA_N81 | CQ4: CPA_N82 | CR4: CPA_O84 | CS4: CPA_P85 | CT4: CPA_Q86 | CU4: CPA_Q87 & Q88 | CV4: CPA_R90 | CW4: CPA_R91 | CX4: CPA_R92 | CY4: CPA_R93 | CZ4: CPA_S94 | DA4: CPA_S95 | DB4: CPA_S96 | DC4: CPA_T97 | DD4: _T | DE4: P3 S1 | DF4: P3 S13 | DG4: P3 S14 | DH4: P3 S15 | DI4: P51G | DJ4: P52 | DK4: P53 | DL4: P61EU | DM4: P61RW | DN4: P62 | DO4: TU
B5: Product | C5: Products of agriculture, hunting and related services | D5: Products of forestry, logging and related services | E5: Fish and other fishing products; aquaculture products; support services to fishing | F5: Coal and lignite | G5: Extraction Of Crude Petroleum And Natural Gas & Mining Of Metal Ores | H5: Other mining and quarrying products | I5: Mining support services | J5: Preserved meat and meat products | K5: Processed and preserved fish, crustaceans, molluscs, fruit and vegetables | L5: Vegetable and animal oils and fats | M5: Dairy products | N5: Grain mill products, starches and starch products | O5: Bakery and farinaceous products | P5: Other food products | Q5: Prepared animal feeds | R5: Alcoholic beverages & Tobacco products | S5: Soft drinks | T5: Textiles | U5: Wearing apparel | V5: Leather and related products | W5: Wood and of products of wood and cork, except furniture; articles of straw and plaiting materials | X5: Paper and paper products | Y5: Printing and recording services | Z5: Coke and refined petroleum products | AA5: Paints, varnishes and similar coatings, printing ink and mastics | AB5: Soap and detergents, cleaning and polishing preparations, perfumes and toilet preparations | AC5: Other chemical products | AD5: Industrial gases, inorganics and fertilisers (all inorganic chemicals) - 20.11/13/15 | AE5: Petrochemicals - 20.14/16/17/60 | AF5: Dyestuffs, agro-chemicals - 20.12/20 | AG5: Basic pharmaceutical products and pharmaceutical preparations | AH5: Rubber and plastic products | AI5: Cement, lime, plaster and articles of concrete, cement and plaster | AJ5: Glass, refractory, clay, other porcelain and ceramic, stone and abrasive products - 23.1-4/7-9 | AK5: Basic iron and steel | AL5: Other basic metals and casting | AM5: Weapons and ammunition | AN5: Fabricated metal products, excl. machinery and equipment and weapons & ammunition - 25.1-3/25.5-9 | AO5: Computer, electronic and optical products | AP5: Electrical equipment | AQ5: Machinery and equipment n.e.c. | AR5: Motor vehicles, trailers and semi-trailers | AS5: Ships and boats | AT5: Air and spacecraft and related machinery | AU5: Other transport equipment - 30.2/4/9 | AV5: Furniture | AW5: Other manufactured goods | AX5: Repair and maintenance of ships and boats | AY5: Repair and maintenance of aircraft and spacecraft | AZ5: Rest of repair; Installation - 33.11-14/17/19/20 | BA5: Electricity, transmission and distribution | BB5: Gas; distribution of gaseous fuels through mains; steam and air conditioning supply | BC5: Natural water; water treatment and supply services | BD5: Sewerage services; sewage sludge | BE5: Waste collection, treatment and disposal services; materials recovery services | BF5: Remediation services and other waste management services | BG5: Construction | BH5: Wholesale and retail trade and repair services of motor vehicles and motorcycles | BI5: Wholesale trade services, except of motor vehicles and motorcycles | BJ5: Retail trade services, except of motor vehicles and motorcycles | BK5: Rail transport services | BL5: Land transport services and transport services via pipelines, excluding rail transport | BM5: Water transport services | BN5: Air transport services | BO5: Warehousing and support services for transportation | BP5: Postal and courier services | BQ5: Accommodation services | BR5: Food and beverage serving services | BS5: Publishing services | BT5: Motion Picture, Video & TV Programme Production, Sound Recording & Music Publishing Activities & Programming And Broadcasting Activities | BU5: Telecommunications services | BV5: Computer programming, consultancy and related services | BW5: Information services | BX5: Financial services, except insurance and pension funding | BY5: Insurance, reinsurance and pension funding services, except compulsory social security | BZ5: Services auxiliary to financial services and insurance services | CA5: Real estate services on a fee or contract basis | CB5: Owner-Occupiers' Housing Services | CC5: Real estate services, excluding on a fee or contract basis and imputed rent | CD5: Legal services | CE5: Accounting, bookkeeping and auditing services; tax consulting services | CF5: Services of head offices; management consulting services | CG5: Architectural and engineering services; technical testing and analysis services | CH5: Scientific research and development services | CI5: Advertising and market research services | CJ5: Other professional, scientific and technical services | CK5: Veterinary services | CL5: Rental and leasing services | CM5: Employment services | CN5: Travel agency, tour operator and other reservation services and related services | CO5: Security and investigation services | CP5: Services to buildings and landscape | CQ5: Office administrative, office support and other business support services | CR5: Public administration and defence services; compulsory social security services | CS5: Education services | CT5: Human health services | CU5: Residential Care & Social Work Activities | CV5: Creative, arts and entertainment services | CW5: Libraries, archives, museums and other cultural services | CX5: Gambling and betting services | CY5: Sports services and amusement and recreation services | CZ5: Services furnished by membership organisations | DA5: Repair services of computers and personal and household goods | DB5: Other personal services | DC5: Services of households as employers of domestic personnel | DD5: Total | DE5: Final consumption expenditure | DF5: Final consumption expenditure by government | DG5: Final consumption expenditure by households | DH5: Final consumption expenditure by non-profit organisations serving households (NPISH) | DI5: Gross fixed capital formation | DJ5: Changes in inventories | DK5: Acquisitions less disposals of valuables | DL5: Exports of goods to EU | DM5: Exports of goods to rest of the world | DN5: Exports of services | DO5: Total Use at basic prices
A6: CPA | B6: Product
A7: CPA_A01 | B7: Products of agriculture, hunting and related services | C7: 4218.7711 | D7: 0.77348643 | E7: 0 | F7: 0 | G7: 0.00049193577 | H7: 1.3299441 | I7: 0 | J7: 4112.8047 | K7: 1087.5966 | L7: 95.720738 | M7: 3145.0956 | N7: 617.99732 | O7: 19.629961 | P7: 91.903281 | Q7: 781.93825 | R7: 242.80811 | S7: 8.0562815 | T7: 0.21210629 | U7: 1.0565443 | V7: 7.2387879 | W7: 0.040899196 | X7: 0.016782505 | Y7: 0.073346633 | Z7: 0.070972239 | AA7: 0.92395505 | AB7: 7.9340726 | AC7: 12.455681 | AD7: 0.091958956 | AE7: 12.902382 | AF7: 0.85947034 | AG7: 152.04463 | AH7: 2.0236691 | AI7: 0.31662946 | AJ7: 0.40373688 | AK7: 0.00036146654 | AL7: 0.0033874957 | AM7: 0.010539312 | AN7: 0.15585892 | AO7: 0.5392405 | AP7: 0.038071094 | AQ7: 0.28384323 | AR7: 0.26198327 | AS7: 0.017644102 | AT7: 0.00092403322 | AU7: 0.14296715 | AV7: 4.4174017 | AW7: 1.538626 | AX7: 0 | AY7: 0.006217021 | AZ7: 3.4102237 | BA7: 61.747208 | BB7: 11.629514 | BC7: 0 | BD7: 0 | BE7: 0 | BF7: 0 | BG7: 80.408855 | BH7: 0.012750638 | BI7: 184.76695 | BJ7: 0.046422639 | BK7: 0 | BL7: 52.774412 | BM7: 0 | BN7: 0 | BO7: 0 | BP7: 7.2091529e-05 | BQ7: 60.564276 | BR7: 172.09497 | BS7: 0.45503073 | BT7: 0 | BU7: 0 | BV7: 30.929395 | BW7: 1.5954631 | BX7: 0.0025436089 | BY7: 0 | BZ7: 0 | CA7: 0 | CB7: 0 | CC7: 112.72525 | CD7: 7.2656652 | CE7: 6.1490237 | CF7: 0 | CG7: 41.109754 | CH7: 23.021988 | CI7: 0 | CJ7: 20.473913 | CK7: 0 | CL7: 38.270313 | CM7: 0.042276423 | CN7: 0 | CO7: 0.00061209983 | CP7: 0 | CQ7: 9.5834447 | CR7: 0 | CS7: 3.456189 | CT7: 15.772097 | CU7: 32.884046 | CV7: 0 | CW7: 0 | CX7: 15.234146 | CY7: 5.1982839 | CZ7: 0 | DA7: 0.86635294 | DB7: 0 | DC7: 0 | DD7: 15623 | DE7: 8222 | DF7: 0 | DG7: 8222 | DH7: 0 | DI7: 1399 | DJ7: 835 | DK7: 0 | DL7: 1406 | DM7: 499 | DN7: 161 | DO7: 28145
A8: CPA_A02 | B8: Products of forestry, logging and related services | C8: 85.651075 | D8: 210.38831 | E8: 0 | F8: 0 | G8: 0 | H8: 0 | I8: 0 | J8: 0 | K8: 0 | L8: 0 | M8: 0 | N8: 0 | O8: 0 | P8: 0 | Q8: 0 | R8: 0 | S8: 0 | T8: 0.92272032 | U8: 0.070418318 | V8: 0.00070588235 | W8: 161.73515 | X8: 149.41798 | Y8: 0.0014295442 | Z8: 0 | AA8: 0.00021939305 | AB8: 0.18553565 | AC8: 0 | AD8: 0.00025561237 | AE8: 0.14632989 | AF8: 0 | AG8: 0 | AH8: 0.0018139297 | AI8: 2.0840628e-05 | AJ8: 0.065760567 | AK8: 0.021660061 | AL8: 0.0064443804 | AM8: 0.00067228945 | AN8: 0.84423563 | AO8: 0 | AP8: 0.052207948 | AQ8: 0.039217756 | AR8: 0.014613493 | AS8: 0.00069340567 | AT8: 0.0014668133 | AU8: 0 | AV8: 5.145819 | AW8: 2.8983936 | AX8: 0.00073340667 | AY8: 0.0010114685 | AZ8: 0.23263952 | BA8: 98.11885 | BB8: 15.355296 | BC8: 0 | BD8: 0 | BE8: 0 | BF8: 0 | BG8: 2.5776968 | BH8: 0.00010841219 | BI8: 12.414696 | BJ8: 0.1426199 | BK8: 0 | BL8: 1.409604 | BM8: 0 | BN8: 0 | BO8: 0 | BP8: 6.2669379e-05 | BQ8: 12.724922 | BR8: 5.7543277 | BS8: 0.016872294 | BT8: 0 | BU8: 0 | BV8: 3.3894428 | BW8: 0.042022823 | BX8: 0.0022111859 | BY8: 0 | BZ8: 0 | CA8: 0 | CB8: 0 | CC8: 12.725551 | CD8: 0.19030414 | CE8: 0.16660945 | CF8: 0 | CG8: 1.018376 | CH8: 0.5920847 | CI8: 0.27830697 | CJ8: 0.81679331 | CK8: 0 | CL8: 9.1138749 | CM8: 0 | CN8: 0 | CO8: 0 | CP8: 0 | CQ8: 0.55523401 | CR8: 0 | CS8: 1.9155426 | CT8: 0 | CU8: 0.88831249 | CV8: 0 | CW8: 0 | CX8: 0 | CY8: 27.076384 | CZ8: 0 | DA8: 0.86635294 | DB8: 0 | DC8: 0 | DD8: 826 | DE8: 108 | DF8: 0 | DG8: 108 | DH8: 0 | DI8: 0 | DJ8: 526 | DK8: 0 | DL8: 12 | DM8: 5 | DN8: 5 | DO8: 1482
A9: CPA_A03 | B9: Fish and other fishing products; aquaculture products; support services to fishing | C9: 0 | D9: 0 | E9: 0 | F9: 0 | G9: 0 | H9: 0 | I9: 0 | J9: 0 | K9: 877.52493 | L9: 0 | M9: 0 | N9: 0 | O9: 0 | P9: 0 | Q9: 0.48670268 | R9: 0 | S9: 0 | T9: 0 | U9: 0 | V9: 0 | W9: 0 | X9: 0 | Y9: 0 | Z9: 0 | AA9: 0 | AB9: 0 | AC9: 0 | AD9: 0 | AE9: 0 | AF9: 0 | AG9: 0.77872429 | AH9: 0 | AI9: 0 | AJ9: 0 | AK9: 0 | AL9: 0 | AM9: 0 | AN9: 0 | AO9: 0 | AP9: 0 | AQ9: 0 | AR9: 0 | AS9: 0 | AT9: 0 | AU9: 0 | AV9: 0 | AW9: 0 | AX9: 0 | AY9: 0 | AZ9: 0 | BA9: 0 | BB9: 0 | BC9: 0 | BD9: 0 | BE9: 0 | BF9: 0 | BG9: 1.6348644e-05 | BH9: 0.26365872 | BI9: 16.930169 | BJ9: 0.93104672 | BK9: 0 | BL9: 12.167567 | BM9: 0 | BN9: 0 | BO9: 0 | BP9: 4.1894825e-11 | BQ9: 20.599665 | BR9: 282.44443 | BS9: 3.066343e-10 | BT9: 0 | BU9: 0 | BV9: 2.725535 | BW9: 0 | BX9: 1.4783132e-09 | BY9: 0 | BZ9: 0 | CA9: 0 | CB9: 0 | CC9: 14.690534 | CD9: 0.87606482 | CE9: 0.77872429 | CF9: 0 | CG9: 2.1414918 | CH9: 1.9482234 | CI9: 0 | CJ9: 1.7521296 | CK9: 0 | CL9: 1.8494702 | CM9: 0 | CN9: 0 | CO9: 0 | CP9: 0 | CQ9: 0.11091579 | CR9: 0 | CS9: 0 | CT9: 0 | CU9: 0 | CV9: 0 | CW9: 0 | CX9: 0 | CY9: 0 | CZ9: 0 | DA9: 0 | DB9: 0 | DC9: 0 | DD9: 1239 | DE9: 0 | DF9: 0 | DG9: 0 | DH9: 0 | DI9: 0 | DJ9: 92 | DK9: -7 | DL9: 454 | DM9: 261 | DN9: 45 | DO9: 2084
A10: CPA_B05 | B10: Coal and lignite | C10: 0 | D10: 0 | E10: 0 | F10: 0 | G10: 0 | H10: 0 | I10: 0 | J10: 0 | K10: 0 | L10: 0 | M10: 0 | N10: 0 | O10: 0 | P10: 0 | Q10: 0 | R10: 0 | S10: 0 | T10: 0 | U10: 0 | V10: 0 | W10: 0 | X10: 0 | Y10: 0 | Z10: 0 | AA10: 0 | AB10: 0 | AC10: 0 | AD10: 0 | AE10: 0 | AF10: 0 | AG10: 0 | AH10: 0 | AI10: 0 | AJ10: 0 | AK10: 0 | AL10: 0 | AM10: 0 | AN10: 0 | AO10: 0 | AP10: 0 | AQ10: 0 | AR10: 0 | AS10: 0 | AT10: 0 | AU10: 0 | AV10: 0 | AW10: 0 | AX10: 0 | AY10: 0 | AZ10: 0 | BA10: 0 | BB10: 0 | BC10: 0 | BD10: 0 | BE10: 0 | BF10: 0 | BG10: 0.00010993846 | BH10: 0 | BI10: 0.019340271 | BJ10: 0.00024420733 | BK10: 0 | BL10: 3.5542544e-05 | BM10: 0 | BN10: 0 | BO10: 0 | BP10: 2.3270062e-05 | BQ10: 1.6184388e-05 | BR10: 0.032039209 | BS10: 0.00017031696 | BT10: 0 | BU10: 0 | BV10: 0.021092532 | BW10: 0.00024437928 | BX10: 0.0008211143 | BY10: 0 | BZ10: 0.00048875855 | CA10: 0 | CB10: 0 | CC10: 5.0474904 | CD10: 4.2835622e-05 | CE10: 0 | CF10: 0 | CG10: 0 | CH10: 0.00076385163 | CI10: 0 | CJ10: 0.012707722 | CK10: 0 | CL10: 0.013196481 | CM10: 0 | CN10: 0 | CO10: 0.0019550342 | CP10: 0.0034213099 | CQ10: 0.0056207234 | CR10: 0 | CS10: 0 | CT10: 0 | CU10: 0 | CV10: 0 | CW10: 0 | CX10: 0 | CY10: 0 | CZ10: 3.840176 | DA10: 0 | DB10: 0 | DC10: 0 | DD10: 9 | DE10: 141 | DF10: 0 | DG10: 141 | DH10: 0 | DI10: 0 | DJ10: 123 | DK10: 0 | DL10: 47 | DM10: 40 | DN10: 0 | DO10: 360
A11: CPA_B06 & B07 | B11: Extraction Of Crude Petroleum And Natural Gas & Mining Of Metal Ores | C11: 1.8225293 | D11: 0 | E11: 0 | F11: 0 | G11: 290.61633 | H11: 6.6497204 | I11: 0.0022687448 | J11: 0 | K11: 0 | L11: 0 | M11: 0 | N11: 0 | O11: 0 | P11: 0.0018836826 | Q11: 0 | R11: 0 | S11: 0 | T11: 0.00065735415 | U11: 0 | V11: 0.00070588235 | W11: 0 | X11: 0.011048983 | Y11: 0.00065735415 | Z11: 551.65047 | AA11: 0.009418413 | AB11: 0.013843132 | AC11: 0.25448277 | AD11: 2.7512302 | AE11: 0.52846135 | AF11: 0.12243937 | AG11: 0.0047533964 | AH11: 0 | AI11: 1.5605668 | AJ11: 0.66090493 | AK11: 0 | AL11: 1.7739777 | AM11: 0 | AN11: 1.8141877 | AO11: 0 | AP11: 0.0084765717 | AQ11: 0.22227455 | AR11: 0 | AS11: 0 | AT11: 0 | AU11: 0 | AV11: 0.013804437 | AW11: 0.016302963 | AX11: 0 | AY11: 0.013852965 | AZ11: 0.0059161873 | BA11: 993.17438 | BB11: 875.06001 | BC11: 0 | BD11: 0 | BE11: 0.00012911556 | BF11: 0 | BG11: 17.629943 | BH11: 0.00089116524 | BI11: 34.73633 | BJ11: 0.079456248 | BK11: 0 | BL11: 6.9222971 | BM11: 0 | BN11: 0 | BO11: 0 | BP11: 0.00020685494 | BQ11: 0.16660144 | BR11: 6.7775146 | BS11: 0.076673813 | BT11: 0.015158627 | BU11: 2.2882487e-06 | BV11: 3.4470182 | BW11: 0.15367558 | BX11: 0.0072978277 | BY11: 0.86395991 | BZ11: 0.0011885054 | CA11: 0 | CB11: 0 | CC11: 37.254581 | CD11: 0.71876475 | CE11: 0.93585175 | CF11: 0.037327506 | CG11: 11.150817 | CH11: 2.3390287 | CI11: 0.22537703 | CJ11: 1.6954607 | CK11: 0 | CL11: 1.0279072 | CM11: 0.012249992 | CN11: 0 | CO11: 0.022225936 | CP11: 0.0039160909 | CQ11: 2.163381 | CR11: 0 | CS11: 4.4151735 | CT11: 0 | CU11: 0.00077740347 | CV11: 0.0040600893 | CW11: 0 | CX11: 0.045743673 | CY11: 2.4355495 | CZ11: 0 | DA11: 0.86635294 | DB11: 0.0015485676 | DC11: 0 | DD11: 2865 | DE11: 0 | DF11: 0 | DG11: 0 | DH11: 0 | DI11: 0 | DJ11: 1234 | DK11: 0 | DL11: 14623 | DM11: 9247 | DN11: 0 | DO11: 27969
A12: CPA_B08 | B12: Other mining and quarrying products | C12: 0 | D12: 0 | E12: 0 | F12: 0 | G12: 0 | H12: 113.17205 | I12: 0 | J12: 0 | K12: 0 | L12: 0 | M12: 0 | N12: 0 | O12: 0 | P12: 0.036689218 | Q12: 0 | R12: 0 | S12: 0 | T12: 2.1802367 | U12: 0.024739412 | V12: 0 | W12: 0.016562931 | X12: 0.17486041 | Y12: 0.49650245 | Z12: 0 | AA12: 1.7938734 | AB12: 0.26091899 | AC12: 4.6593832 | AD12: 49.541283 | AE12: 10.614751 | AF12: 2.2039086 | AG12: 0.37671795 | AH12: 7.2304664 | AI12: 187.49207 | AJ12: 293.87921 | AK12: 5.6075027 | AL12: 1.723956 | AM12: 0.18151815 | AN12: 229.93173 | AO12: 0 | AP12: 1.2200852 | AQ12: 16.021761 | AR12: 2.0746091 | AS12: 0.17327388 | AT12: 0.3960396 | AU12: 0.49629771 | AV12: 2.3860977 | AW12: 4.4063246 | AX12: 0.1980198 | AY12: 0.08417801 | AZ12: 9.9695847 | BA12: 0 | BB12: 0 | BC12: 0 | BD12: 0 | BE12: 0 | BF12: 0 | BG12: 2278.7241 | BH12: 2.5274687e-07 | BI12: 19.364148 | BJ12: 2.0559662 | BK12: 0 | BL12: 10.780837 | BM12: 0 | BN12: 0 | BO12: 0 | BP12: 0.00024235516 | BQ12: 2.3070277 | BR12: 26.705856 | BS12: 0.02296177 | BT12: 2.3785067e-06 | BU12: 1.3018845e-06 | BV12: 3.2315388 | BW12: 0.052678303 | BX12: 0.003299132 | BY12: 0 | BZ12: 0 | CA12: 0 | CB12: 0 | CC12: 23.773744 | CD12: 1.017331 | CE12: 1.1900273 | CF12: 0.072817133 | CG12: 3.5137441 | CH12: 5.6686685 | CI12: 3.7261745e-06 | CJ12: 6.2521878 | CK12: 0 | CL12: 3.1640932 | CM12: 0 | CN12: 0 | CO12: 0.39489292 | CP12: 30.371856 | CQ12: 3.3615447 | CR12: 2.945275 | CS12: 0 | CT12: 0 | CU12: 0 | CV12: 0 | CW12: 0 | CX12: 0 | CY12: 0 | CZ12: 0 | DA12: 0 | DB12: 0 | DC12: 0 | DD12: 3374 | DE12: 29 | DF12: 0 | DG12: 29 | DH12: 0 | DI12: 0 | DJ12: -168 | DK12: 6 | DL12: 596 | DM12: 141 | DN12: 0 | DO12: 3978
A13: CPA_B09 | B13: Mining support services | C13: 0 | D13: 0 | E13: 0 | F13: 0 | G13: 2043.3267 | H13: 256.01423 | I13: 881.92078 | J13: 0 | K13: 0 | L13: 0 | M13: 0 | N13: 0 | O13: 0 | P13: 0 | Q13: 0 | R13: 0 | S13: 0 | T13: 0 | U13: 0 | V13: 0 | W13: 0 | X13: 0 | Y13: 0 | Z13: 0 | AA13: 0 | AB13: 0 | AC13: 0.26097272 | AD13: 6.915777 | AE13: 0 | AF13: 0 | AG13: 0 | AH13: 0 | AI13: 59.827995 | AJ13: 25.44484 | AK13: 0 | AL13: 0 | AM13: 0 | AN13: 12.43395 | AO13: 0 | AP13: 0 | AQ13: 0 | AR13: 0 | AS13: 0 | AT13: 0 | AU13: 0 | AV13: 0 | AW13: 0 | AX13: 0 | AY13: 0 | AZ13: 0 | BA13: 0 | BB13: 0 | BC13: 0 | BD13: 0 | BE13: 0 | BF13: 0 | BG13: 16.886179 | BH13: 0 | BI13: 29.867502 | BJ13: 0 | BK13: 0 | BL13: 129.88342 | BM13: 0 | BN13: 0 | BO13: 0 | BP13: 0 | BQ13: 0 | BR13: 26.504479 | BS13: 0 | BT13: 0 | BU13: 0 | BV13: 10.262716 | BW13: 0.61788005 | BX13: 0 | BY13: 0 | BZ13: 0 | CA13: 0 | CB13: 0 | CC13: 5.2559429 | CD13: 4.0782784 | CE13: 4.4147248 | CF13: 0 | CG13: 100.48637 | CH13: 14.517065 | CI13: 0 | CJ13: 13.981737 | CK13: 0 | CL13: 6.7742489 | CM13: 0 | CN13: 0 | CO13: 0 | CP13: 0 | CQ13: 15.324235 | CR13: 0 | CS13: 0 | CT13: 0 | CU13: 0 | CV13: 0 | CW13: 0 | CX13: 0 | CY13: 0 | CZ13: 0 | DA13: 0 | DB13: 0 | DC13: 0 | DD13: 3665 | DE13: 0 | DF13: 0 | DG13: 0 | DH13: 0 | DI13: 0 | DJ13: 79 | DK13: 0 | DL13: 0 | DM13: 0 | DN13: 661 | DO13: 4405
A14: CPA_C101 | B14: Preserved meat and meat products | C14: 10.023823 | D14: 0.77348643 | E14: 0 | F14: 0 | G14: 7.5333011 | H14: 2.0149215 | I14: 2.425128 | J14: 3983.9318 | K14: 31.868703 | L14: 46.982459 | M14: 17.989416 | N14: 46.241528 | O14: 90.546866 | P14: 602.56818 | Q14: 175.61069 | R14: 44.52484 | S14: 4.2288095 | T14: 0.59781519 | U14: 1.0018056 | V14: 9.96203 | W14: 5.5391122 | X14: 5.9612738 | Y14: 2.2039611 | Z14: 7.0049759 | AA14: 1.5280887 | AB14: 40.588977 | AC14: 10.119252 | AD14: 0.12309429 | AE14: 6.4549432 | AF14: 1.0112788 | AG14: 2.0102998 | AH14: 7.7334026 | AI14: 4.1182302 | AJ14: 1.3642025 | AK14: 0.475353 | AL14: 3.8326114 | AM14: 3.4541593 | AN14: 6.4773352 | AO14: 60.766539 | AP14: 44.990015 | AQ14: 93.501046 | AR14: 33.994304 | AS14: 2.0434474 | AT14: 3.6131724 | AU14: 0.013316373 | AV14: 4.857456 | AW14: 0.81606455 | AX14: 0.090715197 | AY14: 0.9961032 | AZ14: 32.644818 | BA14: 9.3366281 | BB14: 4.4105229 | BC14: 3.6391606 | BD14: 0 | BE14: 2.732515 | BF14: 0 | BG14: 11.038689 | BH14: 136.51521 | BI14: 604.71823 | BJ14: 150.43119 | BK14: 4.9330845 | BL14: 215.87228 | BM14: 20.398902 | BN14: 6.8543086 | BO14: 186.22679 | BP14: 40.584758 | BQ14: 290.85887 | BR14: 2493.7204 | BS14: 11.527006 | BT14: 16.831612 | BU14: 10.703153 | BV14: 86.508988 | BW14: 5.7727244 | BX14: 8.9878374 | BY14: 1.7279198 | BZ14: 1.9649287 | CA14: 0 | CB14: 0 | CC14: 94.378446 | CD14: 0.17644613 | CE14: 1.0035534 | CF14: 0.94521235 | CG14: 3.0200148 | CH14: 53.739843 | CI14: 15.582586 | CJ14: 17.173529 | CK14: 0.97001951 | CL14: 6.6002851 | CM14: 15.729962 | CN14: 13.430951 | CO14: 3.6085831 | CP14: 17.146937 | CQ14: 7.8577253 | CR14: 65.777808 | CS14: 413.20178 | CT14: 248.42309 | CU14: 242.82948 | CV14: 7.6704356 | CW14: 2.969338 | CX14: 18.562817 | CY14: 26.878095 | CZ14: 9.6004399 | DA14: 17.333559 | DB14: 18.940234 | DC14: 0 | DD14: 11117 | DE14: 6966 | DF14: 0 | DG14: 6966 | DH14: 0 | DI14: 0 | DJ14: 11 | DK14: 0 | DL14: 1490 | DM14: 571 | DN14: 228 | DO14: 20383
A15: CPA_C102_3 | B15: Processed and preserved fish, crustaceans, molluscs, fruit and vegetables | C15: 3.6656624 | D15: 0 | E15: 0 | F15: 0 | G15: 4.7160356 | H15: 2.0082917 | I15: 1.6152395 | J15: 69.29706 | K15: 636.12615 | L15: 6.7690095 | M15: 28.680747 | N15: 31.614909 | O15: 168.9374 | P15: 583.35579 | Q15: 5.7037558 | R15: 75.27664 | S15: 129.30554 | T15: 2.9361565 | U15: 0.16742682 | V15: 0.023555377 | W15: 1.8747305 | X15: 3.144001 | Y15: 1.2131535 | Z15: 3.0060023 | AA15: 1.1800703 | AB15: 39.859394 | AC15: 5.4656572 | AD15: 0.090128804 | AE15: 3.7841848 | AF15: 0.019987682 | AG15: 4.3408182 | AH15: 4.9035321 | AI15: 3.172391 | AJ15: 0.40124407 | AK15: 0.34488329 | AL15: 1.9661433 | AM15: 2.4545023 | AN15: 4.3942607 | AO15: 37.433898 | AP15: 27.160652 | AQ15: 64.098927 | AR15: 23.071882 | AS15: 1.987003 | AT15: 2.6874938 | AU15: 0.010794714 | AV15: 3.7699913 | AW15: 1.9563195 | AX15: 0.063729762 | AY15: 0.039892658 | AZ15: 21.635139 | BA15: 5.9445702 | BB15: 2.8966422 | BC15: 2.7293705 | BD15: 0 | BE15: 2.7323859 | BF15: 0 | BG15: 11.559102 | BH15: 92.042804 | BI15: 66.589744 | BJ15: 94.550167 | BK15: 73.996268 | BL15: 202.38566 | BM15: 5.8282577 | BN15: 3.9167478 | BO15: 174.37599 | BP15: 30.562151 | BQ15: 338.92979 | BR15: 922.65687 | BS15: 52.411436 | BT15: 12.352566 | BU15: 5.6327223 | BV15: 51.946721 | BW15: 5.3113847 | BX15: 47.740428 | BY15: 5.1837595 | BZ15: 1.1918362 | CA15: 0 | CB15: 0 | CC15: 76.476354 | CD15: 0.74162205 | CE15: 1.6066804 | CF15: 1.3335431 | CG15: 2.8422014 | CH15: 30.944498 | CI15: 22.114085 | CJ15: 11.436595 | CK15: 0.97001951 | CL15: 4.8921597 | CM15: 9.9795401 | CN15: 6.7154757 | CO15: 2.2235926 | CP15: 12.202126 | CQ15: 147.83111 | CR15: 29.45275 | CS15: 189.0493 | CT15: 109.4259 | CU15: 162.2067 | CV15: 3.9333366 | CW15: 0.68416222 | CX15: 15.077798 | CY15: 72.193696 | CZ15: 8.6403959 | DA15: 11.26816 | DB15: 8.5606432 | DC15: 0 | DD15: 5172 | DE15: 2833 | DF15: 0 | DG15: 2833 | DH15: 0 | DI15: 0 | DJ15: 18 | DK15: 0 | DL15: 925 | DM15: 351 | DN15: 117 | DO15: 9416
A16: CPA_C104 | B16: Vegetable and animal oils and fats | C16: 0.0019750702 | D16: 0 | E16: 0 | F16: 0 | G16: 0.93387873 | H16: 0 | I16: 0 | J16: 3.919112 | K16: 39.250361 | L16: 14.341425 | M16: 0.75990508 | N16: 100.40691 | O16: 139.98405 | P16: 72.975698 | Q16: 18.328298 | R16: 0 | S16: 0 | T16: 0.028551809 | U16: 0.0032611296 | V16: 0.0014117647 | W16: 0.0021869974 | X16: 0.034012774 | Y16: 0.041918972 | Z16: 0 | AA16: 0.87840635 | AB16: 5.6598552 | AC16: 0.82402737 | AD16: 0.0062596807 | AE16: 0.83391326 | AF16: 0 | AG16: 0.034074382 | AH16: 0.92960012 | AI16: 0.0037592348 | AJ16: 0.012595525 | AK16: 1.6536995 | AL16: 0.050802285 | AM16: 0.06473929 | AN16: 0.32615882 | AO16: 4.1321244 | AP16: 0.23756181 | AQ16: 6.2685944 | AR16: 1.943291 | AS16: 0.010122845 | AT16: 0.016228765 | AU16: 0.00046609182 | AV16: 0.01023309 | AW16: 0.040337767 | AX16: 0.0068893912 | AY16: 0.0033020445 | AZ16: 1.9404975 | BA16: 0 | BB16: 0 | BC16: 0 | BD16: 0 | BE16: 0 | BF16: 0 | BG16: 0.18576703 | BH16: 8.110181 | BI16: 9.3982141 | BJ16: 6.9311538 | BK16: 0 | BL16: 18.163575 | BM16: 0 | BN16: 0 | BO16: 0 | BP16: 1.9444572 | BQ16: 18.431342 | BR16: 336.05446 | BS16: 2.7661805 | BT16: 1.6582837 | BU16: 0.91386441 | BV16: 6.1001683 | BW16: 0.05611208 | BX16: 10.24893 | BY16: 0 | BZ16: 0.051333597 | CA16: 0 | CB16: 0 | CC16: 33.982099 | CD16: 0.1037779 | CE16: 0.064290148 | CF16: 0.13612968 | CG16: 0.31712319 | CH16: 4.792728 | CI16: 1.8152158 | CJ16: 2.4680459 | CK16: 0 | CL16: 0.89006464 | CM16: 1.1180098 | CN16: 0 | CO16: 0.039098024 | CP16: 1.8459712 | CQ16: 14.103034 | CR16: 0.98175832 | CS16: 30.905013 | CT16: 16.757853 | CU16: 41.765397 | CV16: 0.97216891 | CW16: 0.052865488 | CX16: 1.9172424 | CY16: 11.355619 | CZ16: 0.96004399 | DA16: 1.7327059 | DB16: 0.0092306809 | DC16: 0 | DD16: 1007 | DE16: 366 | DF16: 0 | DG16: 366 | DH16: 0 | DI16: 0 | DJ16: -27 | DK16: 0 | DL16: 306 | DM16: 50 | DN16: 15 | DO16: 1717
A17: CPA_C105 | B17: Dairy products | C17: 7.2898482 | D17: 0 | E17: 0 | F17: 0 | G17: 3.7816649 | H17: 1.3388611 | I17: 1.6152395 | J17: 36.57853 | K17: 31.878834 | L17: 2.9940641 | M17: 653.16355 | N17: 10.473946 | O17: 418.08166 | P17: 234.25367 | Q17: 0.18508808 | R17: 23.382576 | S17: 1.091618 | T17: 0.9847815 | U17: 0.060022439 | V17: 0.014786776 | W17: 1.8515607 | X17: 4.0224333 | Y17: 1.7075673 | Z17: 4.0004826 | AA17: 0.90586435 | AB17: 15.48744 | AC17: 2.2690558 | AD17: 0.054701138 | AE17: 2.714644 | AF17: 0.019987682 | AG17: 3.7190249 | AH17: 5.3758379 | AI17: 2.0919117 | AJ17: 0.2382018 | AK17: 0.086032411 | AL17: 2.7113676 | AM17: 2.0237413 | AN17: 0.70909608 | AO17: 11.705611 | AP17: 7.077658 | AQ17: 5.5777375 | AR17: 2.899168 | AS17: 0.023897899 | AT17: 1.7300301 | AU17: 0.0065105293 | AV17: 1.8997134 | AW17: 1.9365196 | AX17: 0.014924405 | AY17: 0.034696235 | AZ17: 3.8037851 | BA17: 5.0989784 | BB17: 0.79800169 | BC17: 2.7293705 | BD17: 0 | BE17: 2.7323859 | BF17: 0 | BG17: 6.5844857 | BH17: 81.820373 | BI17: 31.637094 | BJ17: 88.178239 | BK17: 1.9732338 | BL17: 100.90696 | BM17: 12.627892 | BN17: 3.9167478 | BO17: 85.495026 | BP17: 19.948835 | BQ17: 159.41465 | BR17: 506.35593 | BS17: 46.446215 | BT17: 11.38317 | BU17: 6.2431237 | BV17: 45.941762 | BW17: 3.4095834 | BX17: 25.024537 | BY17: 2.5918797 | BZ17: 25.621785 | CA17: 0 | CB17: 0 | CC17: 39.965345 | CD17: 0.021327336 | CE17: 0.12585323 | CF17: 0.65145945 | CG17: 1.1330681 | CH17: 18.904526 | CI17: 18.464884 | CJ17: 8.3055674 | CK17: 0 | CL17: 3.4482396 | CM17: 8.5928635 | CN17: 6.7154757 | CO17: 2.1843743 | CP17: 10.855078 | CQ17: 5.5190138 | CR17: 2.945275 | CS17: 149.22858 | CT17: 40.424374 | CU17: 41.768506 | CV17: 4.8391908 | CW17: 0.65219735 | CX17: 21.307461 | CY17: 43.809054 | CZ17: 6.7203079 | DA17: 12.132655 | DB17: 8.5371236 | DC17: 0 | DD17: 3248 | DE17: 4465 | DF17: 0 | DG17: 4465 | DH17: 0 | DI17: 0 | DJ17: 364 | DK17: 0 | DL17: 1120 | DM17: 363 | DN17: 133 | DO17: 9693
A18: CPA_C106 | B18: Grain mill products, starches and starch products | C18: 0 | D18: 0 | E18: 0 | F18: 0 | G18: 0 | H18: 0 | I18: 0 | J18: 176.05311 | K18: 11.790359 | L18: 78.436284 | M18: 5.5437738 | N18: 495.53807 | O18: 683.04983 | P18: 82.939604 | Q18: 566.29468 | R18: 488.08142 | S18: 1.2878344 | T18: 0.02882465 | U18: 0.0016565891 | V18: 0 | W18: 0 | X18: 3.7514263 | Y18: 0 | Z18: 0 | AA18: 0.64855591 | AB18: 5.4367986 | AC18: 5.6125751 | AD18: 0 | AE18: 3.9123542 | AF18: 0 | AG18: 0.56828358 | AH18: 0.26142729 | AI18: 0 | AJ18: 0.18695828 | AK18: 0 | AL18: 0 | AM18: 0 | AN18: 0.092650844 | AO18: 0 | AP18: 0 | AQ18: 0.022962597 | AR18: 0 | AS18: 0 | AT18: 0 | AU18: 0 | AV18: 0 | AW18: 0.04406527 | AX18: 0 | AY18: 0 | AZ18: 0 | BA18: 0 | BB18: 0 | BC18: 0 | BD18: 0 | BE18: 0 | BF18: 0 | BG18: 0.67579349 | BH18: 0.37543845 | BI18: 106.97049 | BJ18: 13.316451 | BK18: 0 | BL18: 3.7231358 | BM18: 0 | BN18: 0 | BO18: 0 | BP18: 0.00017113142 | BQ18: 2.8966898 | BR18: 312.87061 | BS18: 0.01059181 | BT18: 0.11620883 | BU18: 1.4183265e-06 | BV18: 7.4079968 | BW18: 0.0090268837 | BX18: 0.0060396851 | BY18: 0 | BZ18: 0.94921114 | CA18: 0 | CB18: 0 | CC18: 15.078056 | CD18: 0.47141269 | CE18: 1.7062253 | CF18: 0.46985897 | CG18: 1.5374556 | CH18: 14.546701 | CI18: 1.7370533 | CJ18: 0.78824959 | CK18: 0 | CL18: 3.1180954 | CM18: 0.095730745 | CN18: 0 | CO18: 0.016066918 | CP18: 0.019713989 | CQ18: 1.8767392 | CR18: 3.9270333 | CS18: 89.15454 | CT18: 24.643901 | CU18: 68.961469 | CV18: 0.031127351 | CW18: 0.071917766 | CX18: 1.2210691 | CY18: 18.655659 | CZ18: 0 | DA18: 0 | DB18: 0.96056406 | DC18: 0 | DD18: 3308 | DE18: 1177 | DF18: 0 | DG18: 1177 | DH18: 0 | DI18: 0 | DJ18: 123 | DK18: 0 | DL18: 608 | DM18: 267 | DN18: 42 | DO18: 5525
... A112: _T | B112: Total | C112: 16295.459 | D112: 699.23173 | E112: 1011.9285 | F112: 193.77049 | G112: 9535.5409 | H112: 1951.9198 | I112: 2347.3345 | J112: 14043.508 | K112: 6217.1961 | L112: 876.61819 | M112: 7009.9735 | N112: 3281.3277 | O112: 5934.387 | P112: 8166.9158 | Q112: 4417.7897 | R112: 5026.1758 | S112: 2841.9876 | T112: 1840.1527 | U112: 1309.7523 | V112: 356.09049 | W112: 2489.9589 | X112: 4963.4732 | Y112: 3234.2441 | Z112: 3524.7304 | AA112: 1171.6876 | AB112: 2766.8907 | AC112: 2020.4669 | AD112: 1241.0393 | AE112: 4623.8204 | AF112: 836.59212 | AG112: 7867.9031 | AH112: 7393.0379 | AI112: 3906.4714 | AJ112: 3075.2934 | AK112: 3429.4145 | AL112: 1348.666 | AM112: 1470.0777 | AN112: 9407.2153 | AO112: 7989.7201 | AP112: 4296.6901 | AQ112: 10328.764 | AR112: 23316.184 | AS112: 2183.872 | AT112: 11362.366 | AU112: 1048.1471 | AV112: 2856.0287 | AW112: 3273.0124 | AX112: 232.54744 | AY112: 2213.9449 | AZ112: 7556.5628 | BA112: 55400.584 | BB112: 28080.883 | BC112: 3109.6627 | BD112: 1668.5698 | BE112: 10275.916 | BF112: 320.97561 | BG112: 196032.7 | BH112: 21804.995 | BI112: 65886.343 | BJ112: 50895.537 | BK112: 9281.1053 | BL112: 22672.444 | BM112: 7028.8772 | BN112: 11792.348 | BO112: 19777.285 | BP112: 8683.6381 | BQ112: 10583.217 | BR112: 44625.908 | BS112: 9190.0083 | BT112: 17739.343 | BU112: 11621.296 | BV112: 32625.007 | BW112: 4278.3765 | BX112: 67935.03 | BY112: 20705.663 | BZ112: 27220.169 | CA112: 3693.5025 | CB112: 30716 | CC112: 47842.607 | CD112: 7880.8406 | CE112: 3900.2428 | CF112: 17354.97 | CG112: 20559.327 | CH112: 22117.474 | CI112: 18401.341 | CJ112: 14321.193 | CK112: 1187.3039 | CL112: 13360.238 | CM112: 17451.152 | CN112: 11238.828 | CO112: 2833.7047 | CP112: 10707.812 | CQ112: 18756.336 | CR112: 57883.489 | CS112: 36088.969 | CT112: 49780.784 | CU112: 26440.477 | CV112: 5168.1152 | CW112: 2079.2956 | CX112: 4164.8122 | CY112: 5667.45 | CZ112: 6013.2661 | DA112: 1106.4669 | DB112: 5296.2372 | DC112: 0 | DD112: 1456034 | DE112: 1458586 | DF112: 420413 | DG112: 985538 | DH112: 52635 | DI112: 311216 | DJ112: 2785 | DK112: 2873 | DL112: 130361 | DM112: 129668 | DN112: 332910 | DO112: 3824433
B113: Use of imported products, cif | C113: 651.50325 | D113: 20.110647 | E113: 319.8076 | F113: 6.8852459 | G113: 1160.3381 | H113: 646.61307 | I113: 790.70619 | J113: 1002.7944 | K113: 562.13934 | L113: 503.03464 | M113: 345.28102 | N113: 1064.721 | O113: 411.50791 | P113: 1423.3258 | Q113: 604.90353 | R113: 714.51914 | S113: 352.80097 | T113: 1025.945 | U113: 244.76873 | V113: 142.87797 | W113: 2377.9445 | X113: 2737.7412 | Y113: 1787.0874 | Z113: 22874.039 | AA113: 723.90023 | AB113: 1477.9339 | AC113: 1924.7307 | AD113: 1003.2013 | AE113: 3270.5525 | AF113: 664.36387 | AG113: 4725.9561 | AH113: 6451.4445 | AI113: 1260.8748 | AJ113: 1304.6913 | AK113: 2177.9637 | AL113: 2581.467 | AM113: 394.27507 | AN113: 6442.7183 | AO113: 2965.2699 | AP113: 3364.3875 | AQ113: 7464.143 | AR113: 19861.731 | AS113: 437.79813 | AT113: 4247.7087 | AU113: 740.62651 | AV113: 1158.4925 | AW113: 1731.6609 | AX113: 64.15355 | AY113: 551.35294 | AZ113: 3719.1779 | BA113: 5132.4044 | BB113: 2938.6121 | BC113: 154.66433 | BD113: 28.035067 | BE113: 2555.7027 | BF113: 11.707317 | BG113: 9542.538 | BH113: 4272.14 | BI113: 18145.326 | BJ113: 7187.6806 | BK113: 487.38875 | BL113: 3568.1624 | BM113: 992.95224 | BN113: 6646.721 | BO113: 2498.8249 | BP113: 1339.8707 | BQ113: 708.9805 | BR113: 5147.5332 | BS113: 1698.372 | BT113: 4249.8287 | BU113: 5455.3481 | BV113: 10726.025 | BW113: 1146.9979 | BX113: 6360.9492 | BY113: 7704.7945 | BZ113: 6757.7837 | CA113: 214.07987 | CB113: 14 | CC113: 3276.9264 | CD113: 1227.6857 | CE113: 1301.4811 | CF113: 9419.3019 | CG113: 6201.2183 | CH113: 4702.9245 | CI113: 2528.4232 | CJ113: 1272.5705 | CK113: 172.66347 | CL113: 1706.7756 | CM113: 2699.8211 | CN113: 2816.6624 | CO113: 173.88543 | CP113: 395.16169 | CQ113: 5110.9232 | CR113: 7498.6701 | CS113: 2467.4275 | CT113: 10385.092 | CU113: 765.73374 | CV113: 435.21275 | CW113: 237.03316 | CX113: 355.22904 | CY113: 903.67664 | CZ113: 672.89569 | DA113: 278.88924 | DB113: 629.32119 | DC113: 0 | DD113: 305805 | DE113: 280148 | DF113: 5166 | DG113: 274980 | DH113: 2 | DI113: 53419 | DJ113: -154 | DK113: 2 | DL113: 36521 | DM113: 59563 | DN113: 498 | DO113: 735802
B114: Taxes less subsidies on products | C114: 436.50502 | D114: 13.149269 | E114: 27.684837 | F114: 3.9344262 | G114: 113.15631 | H114: 77.872745 | I114: 9.2944602 | J114: 55.855945 | K114: 12.528476 | L114: 6.012484 | M114: 17.627399 | N114: 11.877265 | O114: 31.146458 | P114: 30.644307 | Q114: 24.033042 | R114: 276.1565 | S114: 20.582503 | T114: 12.714582 | U114: 4.4309692 | V114: 1.9259187 | W114: 26.059068 | X114: 40.030555 | Y114: 18.606039 | Z114: 840.63656 | AA114: 9.4571071 | AB114: 15.530211 | AC114: 22.942443 | AD114: 21.086728 | AE114: 195.11134 | AF114: 9.051613 | AG114: 43.624207 | AH114: 73.989139 | AI114: 106.59361 | AJ114: 136.76156 | AK114: 64.455436 | AL114: 14.471281 | AM114: 5.1360948 | AN114: 94.102532 | AO114: 32.873117 | AP114: 25.980358 | AQ114: 73.787702 | AR114: 189.80809 | AS114: 25.418616 | AT114: 53.423409 | AU114: 11.035302 | AV114: 21.967917 | AW114: 27.184785 | AX114: 1.3377454 | AY114: 8.6078133 | AZ114: 90.476732 | BA114: 888.38489 | BB114: 219.52038 | BC114: 31.842655 | BD114: 132.44152 | BE114: 1602.1123 | BF114: 5.8536585 | BG114: 6584.8359 | BH114: 271.42605 | BI114: 1813.0827 | BJ114: 619.97348 | BK114: 3.9464676 | BL114: 1775.4599 | BM114: 384.85099 | BN114: 2204.1498 | BO114: 448.63726 | BP114: 930.7313 | BQ114: 660.58898 | BR114: 3065.1436 | BS114: 28.812301 | BT114: 85.793464 | BU114: 71.416731 | BV114: 420.86254 | BW114: 35.701426 | BX114: 6427.3938 | BY114: 2381.0735 | BZ114: 2785.5608 | CA114: 47.48075 | CB114: 237 | CC114: 1184.1394 | CD114: 32.906214 | CE114: 51.775487 | CF114: 328.83569 | CG114: 168.1231 | CH114: 250.55731 | CI114: 150.13276 | CJ114: 171.91155 | CK114: 12.610254 | CL114: 266.37979 | CM114: 68.701934 | CN114: 486.39231 | CO114: 28.215124 | CP114: 85.787831 | CQ114: 282.11059 | CR114: 6784.9318 | CS114: 2995.9778 | CT114: 6502.1167 | CU114: 2611.0624 | CV114: 639.81575 | CW114: 20.652707 | CX114: 241.85975 | CY114: 695.90641 | CZ114: 122.22097 | DA114: 5.2272984 | DB114: 597.89185 | DC114: 0 | DD114: 62437 | DE114: 126886 | DF114: 0 | DG114: 127146 | DH114: -260 | DI114: 38730 | DJ114: 0 | DK114: 5 | DL114: 3777 | DM114: 3612 | DN114: 2744 | DO114: 238191
B115: Total intermediate use at purchaser's prices | C115: 17383.468 | D115: 732.49165 | E115: 1359.421 | F115: 204.59016 | G115: 10809.035 | H115: 2676.4056 | I115: 3147.3352 | J115: 15102.159 | K115: 6791.8639 | L115: 1385.6653 | M115: 7372.8819 | N115: 4357.926 | O115: 6377.0414 | P115: 9620.8859 | Q115: 5046.7263 | R115: 6016.8515 | S115: 3215.371 | T115: 2878.8123 | U115: 1558.952 | V115: 500.89438 | W115: 4893.9625 | X115: 7741.245 | Y115: 5039.9375 | Z115: 27239.406 | AA115: 1905.045 | AB115: 4260.3548 | AC115: 3968.14 | AD115: 2265.3273 | AE115: 8089.4843 | AF115: 1510.0076 | AG115: 12637.483 | AH115: 13918.472 | AI115: 5273.9398 | AJ115: 4516.7462 | AK115: 5671.8336 | AL115: 3944.6043 | AM115: 1869.4889 | AN115: 15944.036 | AO115: 10987.863 | AP115: 7687.058 | AQ115: 17866.694 | AR115: 43367.723 | AS115: 2647.0888 | AT115: 15663.498 | AU115: 1799.8089 | AV115: 4036.4891 | AW115: 5031.858 | AX115: 298.03873 | AY115: 2773.9057 | AZ115: 11366.217 | BA115: 61421.373 | BB115: 31239.015 | BC115: 3296.1697 | BD115: 1829.0464 | BE115: 14433.731 | BF115: 338.53659 | BG115: 212160.07 | BH115: 26348.561 | BI115: 85844.752 | BJ115: 58703.192 | BK115: 9772.4405 | BL115: 28016.066 | BM115: 8406.6804 | BN115: 20643.219 | BO115: 22724.747 | BP115: 10954.24 | BQ115: 11952.787 | BR115: 52838.585 | BS115: 10917.193 | BT115: 22074.965 | BU115: 17148.061 | BV115: 43771.894 | BW115: 5461.0759 | BX115: 80723.373 | BY115: 30791.531 | BZ115: 36763.514 | CA115: 3955.0632 | CB115: 30967 | CC115: 52303.673 | CD115: 9141.4325 | CE115: 5253.4994 | CF115: 27103.108 | CG115: 26928.669 | CH115: 27070.955 | CI115: 21079.897 | CJ115: 15765.675 | CK115: 1372.5776 | CL115: 15333.394 | CM115: 20219.675 | CN115: 14541.883 | CO115: 3035.8053 | CP115: 11188.762 | CQ115: 24149.37 | CR115: 72167.091 | CS115: 41552.374 | CT115: 66667.992 | CU115: 29817.273 | CV115: 6243.1437 | CW115: 2336.9814 | CX115: 4761.901 | CY115: 7267.033 | CZ115: 6808.3828 | DA115: 1390.5834 | DB115: 6523.4502 | DC115: 0 | DD115: 1824276 | DE115: 1865620 | DF115: 425579 | DG115: 1387664 | DH115: 52377 | DI115: 403365 | DJ115: 2631 | DK115: 2880 | DL115: 170659 | DM115: 192843 | DN115: 336152 | DO115: 4798426
A116: D1 | B116: Compensation of employees | C116: 3338.2018 | D116: 391.38413 | E116: 370.40403 | F116: 78.688525 | G116: 2127.2829 | H116: 622.76034 | I116: 955.32626 | J116: 3872.798 | K116: 1857.1321 | L116: 243.12227 | M116: 1169.2412 | N116: 706.86891 | O116: 3098.481 | P116: 3635.988 | Q116: 718.81887 | R116: 1263.9981 | S116: 659.06287 | T116: 2262.9503 | U116: 1526.9163 | V116: 293.82627 | W116: 2079.5596 | X116: 3398.563 | Y116: 2792.728 | Z116: 800.401 | AA116: 964.81496 | AB116: 2255.9749 | AC116: 1058.0606 | AD116: 429.92112 | AE116: 1544.9044 | AF116: 580.72364 | AG116: 5519.8038 | AH116: 5757.57 | AI116: 2011.1456 | AJ116: 1737.4068 | AK116: 1687.1159 | AL116: 1250.9486 | AM116: 858.34335 | AN116: 10184.223 | AO116: 10056.901 | AP116: 3771.7364 | AQ116: 7039.6459 | AR116: 9476.1517 | AS116: 1624.6755 | AT116: 4770.22 | AU116: 597.36366 | AV116: 2967.413 | AW116: 3025.8331 | AX116: 320.83539 | AY116: 1244.2502 | AZ116: 6279.0622 | BA116: 4747.6526 | BB116: 2796.789 | BC116: 1984.2523 | BD116: 1492.6256 | BE116: 4395.1968 | BF116: 194.14634 | BG116: 54191.344 | BH116: 22492.241 | BI116: 59862.782 | BJ116: 54182.125 | BK116: 4074.7278 | BL116: 18072.979 | BM116: 3327.5094 | BN116: 4037.1878 | BO116: 15202.031 | BP116: 10532.674 | BQ116: 10928.828 | BR116: 44273.429 | BS116: 7249.4889 | BT116: 7697.6325 | BU116: 16285.264 | BV116: 40795.494 | BW116: 4355.1927 | BX116: 39738.515 | BY116: 7281.4541 | BZ116: 25638.415 | CA116: 4007.5419 | CB116: 0 | CC116: 20713.567 | CD116: 13083.725 | CE116: 11498.596 | CF116: 20734.152 | CG116: 15872.039 | CH116: 17028.977 | CI116: 12459.475 | CJ116: 9533.6356 | CK116: 2664.6436 | CL116: 14140.086 | CM116: 23394.023 | CN116: 6327.8968 | CO116: 2304.2466 | CP116: 5988.3464 | CQ116: 15641.693 | CR116: 67601.915 | CS116: 81393.867 | CT116: 79453.13 | CU116: 40680.56 | CV116: 3387.4711 | CW116: 2091.2923 | CX116: 2645.2506 | CY116: 7299.529 | CZ116: 7403.9635 | DA116: 1215.1097 | DB116: 6565.741 | DC116: 3917 | DD116: 1090157
A117: GOS & MI | B117: Gross operating surplus and mixed income | C117: 9256.499 | D117: 360.44468 | E117: 350.35639 | F117: 88.52459 | G117: 14897.178 | H117: 645.7875 | I117: 281.22923 | J117: 1408.2088 | K117: 774.95584 | L117: 133.78755 | M117: 1170.4388 | N117: 479.36007 | O117: 933.29344 | P117: 1807.1515 | Q117: 557.11259 | R117: 2301.5224 | S117: 1077.9683 | T117: 1439.3968 | U117: 933.77867 | V117: 222.01438 | W117: 1296.2946 | X117: 1221.1199 | Y117: 1261.5792 | Z117: 2545.4099 | AA117: 329.66855 | AB117: 2167.9029 | AC117: 954.82145 | AD117: 342.49539 | AE117: 1154.9849 | AF117: 488.58608 | AG117: 6986.6151 | AH117: 1417.6387 | AI117: 1450.0747 | AJ117: 816.2281 | AK117: 784.73911 | AL117: 817.77037 | AM117: 200.18544 | AN117: 4589.746 | AO117: 3569.392 | AP117: 1129.5117 | AQ117: 4328.8023 | AR117: 5639.6618 | AS117: 488.82124 | AT117: 2377.3635 | AU117: 344.84767 | AV117: 1006.3904 | AW117: 1636.8432 | AX117: 193.20555 | AY117: 584.78953 | AZ117: 3274.7229 | BA117: 13110.325 | BB117: 5869.9611 | BC117: 5081.178 | BD117: 6254.7201 | BE117: 2295.7199 | BF117: 224.39024 | BG117: 68728.836 | BH117: 5425.7731 | BI117: 31449.036 | BJ117: 30529.802 | BK117: 1290.4949 | BL117: 6567.565 | BM117: 3035.9618 | BN117: 1465.8429 | BO117: 5144.9383 | BP117: 3556.7059 | BQ117: 5952.3931 | BR117: 14145.678 | BS117: 5106.5954 | BT117: 9942.6805 | BU117: 13514.743 | BV117: 12300.651 | BW117: 2857.8723 | BX117: 34552.134 | BY117: 18800.632 | BZ117: 21153.286 | CA117: 1623.5084 | CB117: 185717 | CC117: 66798.7 | CD117: 15746.313 | CE117: 6935.9169 | CF117: 6896.1165 | CG117: 3970.0862 | CH117: 9481.364 | CI117: 11967.801 | CJ117: 3023.7845 | CK117: 1557.8513 | CL117: 13293.389 | CM117: 5556.1269 | CN117: 3934.3094 | CO117: 1600.3592 | CP117: 4776.1567 | CQ117: 8078.6587 | CR117: 28416.995 | CS117: 23949.231 | CT117: 24355.073 | CU117: 5956.4907 | CV117: 4669.4264 | CW117: 832.00767 | CX117: 2440.0735 | CY117: 3226.1863 | CZ117: 1531.1862 | DA117: 1064.5992 | DB117: 14816.152 | DC117: 0 | DD117: 883092
A118: D29-D39 | B118: Taxes less subsidies on production | C118: -1833.1685 | D118: -2.3204593 | E118: 3.8185983 | F118: -11.803279 | G118: 135.50405 | H118: 33.046587 | I118: 21.109336 | J118: -0.16543387 | K118: -7.9518647 | L118: -45.575129 | M118: -19.561978 | N118: -19.154951 | O118: 33.184201 | P118: 46.974566 | Q118: -21.657782 | R118: -10.371993 | S118: -22.402199 | T118: 7.8406561 | U118: -12.646975 | V118: -31.735028 | W118: 25.18334 | X118: 63.072065 | Y118: 48.755253 | Z118: 114.78258 | AA118: -20.528472 | AB118: -4.2325415 | AC118: -16.022107 | AD118: -8.7438266 | AE118: 13.626467 | AF118: -34.317322 | AG118: 30.097644 | AH118: 119.31977 | AI118: 79.839883 | AJ118: 49.618812 | AK118: 98.311338 | AL118: 1.6767282 | AM118: -20.017668 | AN118: 250.99464 | AO118: 93.844068 | AP118: 44.693891 | AQ118: 124.85749 | AR118: 126.46398 | AS118: -22.585516 | AT118: 15.918659 | AU118: -28.020193 | AV118: 140.70753 | AW118: 47.46567 | AX118: -20.079668 | AY118: -23.945378 | AZ118: 42.997471 | BA118: 1740.649 | BB118: 745.2345 | BC118: 520.39997 | BD118: 127.60789 | BE118: 160.35227 | BF118: 2.9268293 | BG118: 1674.745 | BH118: 1093.4244 | BI118: 1927.4299 | BJ118: 6699.8815 | BK118: 196.33676 | BL118: 776.39048 | BM118: 107.84842 | BN118: 11.750243 | BO118: 919.28315 | BP118: 267.38013 | BQ118: 891.99205 | BR118: 2735.3078 | BS118: -9.2769188 | BT118: -1264.2778 | BU118: 489.93246 | BV118: 480.96009 | BW118: -26.140847 | BX118: 2222.9769 | BY118: 537.38306 | BZ118: 345.78521 | CA118: 279.88652 | CB118: 0 | CC118: -992.93989 | CD118: 370.52921 | CE118: 113.98804 | CF118: 541.62386 | CG118: 328.20652 | CH118: 55.703583 | CI118: -98.172856 | CJ118: 173.9052 | CK118: -127.07256 | CL118: 392.13139 | CM118: 217.17549 | CN118: 72.910879 | CO118: 23.588881 | CP118: 102.73516 | CQ118: 492.27791 | CR118: 0 | CS118: 542.5269 | CT118: 158.80444 | CU118: 321.67625 | CV118: 34.958833 | CW118: 28.718592 | CX118: 158.77488 | CY118: 382.25168 | CZ118: 104.46755 | DA118: 27.707592 | DB118: 248.6565 | DC118: 0 | DD118: 26908
A119: GVA | B119: Gross value added | C119: 10761.532 | D119: 749.50835 | E119: 724.57902 | F119: 155.40984 | G119: 17159.965 | H119: 1301.5944 | I119: 1257.6648 | J119: 5280.8414 | K119: 2624.1361 | L119: 331.33469 | M119: 2320.1181 | N119: 1167.074 | O119: 4064.9586 | P119: 5490.1141 | Q119: 1254.2737 | R119: 3555.1485 | S119: 1714.629 | T119: 3710.1877 | U119: 2448.048 | V119: 484.10562 | W119: 3401.0375 | X119: 4682.755 | Y119: 4103.0625 | Z119: 3460.5935 | AA119: 1273.955 | AB119: 4419.6452 | AC119: 1996.86 | AD119: 763.67269 | AE119: 2713.5157 | AF119: 1034.9924 | AG119: 12536.517 | AH119: 7294.5285 | AI119: 3541.0602 | AJ119: 2603.2538 | AK119: 2570.1664 | AL119: 2070.3957 | AM119: 1038.5111 | AN119: 15024.964 | AO119: 13720.137 | AP119: 4945.942 | AQ119: 11493.306 | AR119: 15242.277 | AS119: 2090.9112 | AT119: 7163.5022 | AU119: 914.19113 | AV119: 4114.5109 | AW119: 4710.142 | AX119: 493.96127 | AY119: 1805.0943 | AZ119: 9596.7826 | BA119: 19598.627 | BB119: 9411.9846 | BC119: 7585.8303 | BD119: 7874.9536 | BE119: 6851.2689 | BF119: 421.46341 | BG119: 124594.93 | BH119: 29011.439 | BI119: 93239.248 | BJ119: 91411.808 | BK119: 5561.5595 | BL119: 25416.934 | BM119: 6471.3196 | BN119: 5514.7809 | BO119: 21266.253 | BP119: 14356.76 | BQ119: 17773.213 | BR119: 61154.415 | BS119: 12346.807 | BT119: 16376.035 | BU119: 30289.939 | BV119: 53577.106 | BW119: 7186.9241 | BX119: 76513.627 | BY119: 26619.469 | BZ119: 47137.486 | CA119: 5910.9368 | CB119: 185717 | CC119: 86519.327 | CD119: 29200.567 | CE119: 18548.501 | CF119: 28171.892 | CG119: 20170.331 | CH119: 26566.045 | CI119: 24329.103 | CJ119: 12731.325 | CK119: 4095.4224 | CL119: 27825.606 | CM119: 29167.325 | CN119: 10335.117 | CO119: 3928.1947 | CP119: 10867.238 | CQ119: 24212.63 | CR119: 96018.909 | CS119: 105885.63 | CT119: 103967.01 | CU119: 46958.727 | CV119: 8091.8563 | CW119: 2952.0186 | CX119: 5244.099 | CY119: 10907.967 | CZ119: 9039.6172 | DA119: 2307.4166 | DB119: 21630.55 | DC119: 3917 | DD119: 2000157
